Workbook
Name SegmentaciónDeDatos_COD: #N/A
Name SegmentaciónDeDatos_ESTADO: #N/A

Sheet  Elementos Refuellers
A1: FECHA | D1: =TODAY() -> 46017 | E1: ALERTA DE VIGILANCIA 120 DIAS O NENOS
A3: REFUELLERS
A4: DATOS VEHICULOS | K4: FILTRACION | Q4: ESTADO
A5: # | B5: SUP | C5: COD | D5: MARCA | E5: REF | F5: MOVIL | G5: PLACA | H5: MOD | I5: CAP | J5: PRODUCTO | K5: FILTRACION | L5: MARCA | M5: CANT | N5: 1º ETAPA | O5: CANT | P5: 2º ETAPA | Q5: PROXIMO CAMBIO | R5: DIAS DE VIGILANCIA | S5: ESTADO | T5: CONDICION | U5: V 1° | V5: V 2°
A6: 1 | B6: HC | C6: GAA | D6: CHEVROLET | E6: NKR | F6: MOV 050 | G6: SLJ-437 | H6: 2008 | I6: 1360 | J6: AV Gas | K6: Monitor | L6: Facet | M6: 2 | N6: ACO 51201R | O6: 0 | P6: N/A | Q6: 46096 | R6: =REFUELLERS[[#This Row],[PROXIMO CAMBIO]]-$D$1 -> 79 | S6: =IF($D$1<=REFUELLERS[[#This Row],[PROXIMO CAMBIO]],"VIGENTE","VENCIDO") -> VIGENTE | T6: SATURADOS | U6: =IFERROR(LOOKUP("SATURADOS",REFUELLERS[[#This Row],[CONDICION]],REFUELLERS[[#This Row],[CANT]]),0) -> 2 | V6: =IFERROR(LOOKUP("SATURADOS",REFUELLERS[[#This Row],[CONDICION]],REFUELLERS[[#This Row],[CANT ]]),0) -> 0
A7: =A6+1 -> 2 | B7: ORA | C7: PEI | D7: CHEVROLET | E7: KODIAK | F7: MOV 051 | G7: UFQ-586 | H7: 1998 | I7: 4100 | J7: JET A-1 | K7: Separador | L7: Facet | M7: 3 | N7: CAA33-5SB | O7: 1 | P7: SS436FB-5 | Q7: 46600 | R7: =REFUELLERS[[#This Row],[PROXIMO CAMBIO]]-$D$1 -> 583 | S7: =IF($D$1<=REFUELLERS[[#This Row],[PROXIMO CAMBIO]],"VIGENTE","VENCIDO") -> VIGENTE | U7: =IFERROR(LOOKUP("SATURADOS",REFUELLERS[[#This Row],[CONDICION]],REFUELLERS[[#This Row],[CANT]]),0) -> 0 | V7: =IFERROR(LOOKUP("SATURADOS",REFUELLERS[[#This Row],[CONDICION]],REFUELLERS[[#This Row],[CANT ]]),0) -> 0
A8: =A7+1 -> 3 | B8: OEO | C8: MED | D8: CHEVROLET | E8: KODIAK | F8: MOV 053 | G8: UFT-131 | H8: 2003 | I8: 5100 | J8: JET A-1 | K8: Separador | L8: Velcon | M8: 2 | N8: I-633C5TB | O8: 1 | P8: SO-436V | Q8: 46872 | R8: =REFUELLERS[[#This Row],[PROXIMO CAMBIO]]-$D$1 -> 855 | S8: =IF($D$1<=REFUELLERS[[#This Row],[PROXIMO CAMBIO]],"VIGENTE","VENCIDO") -> VIGENTE | U8: =IFERROR(LOOKUP("SATURADOS",REFUELLERS[[#This Row],[CONDICION]],REFUELLERS[[#This Row],[CANT]]),0) -> 0 | V8: =IFERROR(LOOKUP("SATURADOS",REFUELLERS[[#This Row],[CONDICION]],REFUELLERS[[#This Row],[CANT ]]),0) -> 0
A9: =A8+1 -> 4 | B9: GN | C9: BAQ | D9: CHEVROLET | E9: KODIAK | F9: MOV 056 | G9: VEG-911 | H9: 2006 | I9: 3500 | J9: JET A-1 | K9: Separador | L9: Facet | M9: 3 | N9: CAA33-5SB | O9: 1 | P9: SS436FB-5 | Q9: 44368 | R9: =REFUELLERS[[#This Row],[PROXIMO CAMBIO]]-$D$1 -> -1649 | S9: =IF($D$1<=REFUELLERS[[#This Row],[PROXIMO CAMBIO]],"VIGENTE","VENCIDO") -> VENCIDO | T9: SATURADOS | U9: =IFERROR(LOOKUP("SATURADOS",REFUELLERS[[#This Row],[CONDICION]],REFUELLERS[[#This Row],[CANT]]),0) -> 3 | V9: =IFERROR(LOOKUP("SATURADOS",REFUELLERS[[#This Row],[CONDICION]],REFUELLERS[[#This Row],[CANT ]]),0) -> 1
A10: =A9+1 -> 5 | B10: ORA | C10: PEI | D10: KW DART | E10: 80FTDR | F10: MOV 057 | G10: T-6743 | H10: 1970 | I10: 8000 | J10: JET A-1 | K10: Monitor | L10: Facet | M10: 27 | N10: FG-230-7 | O10: 0 | P10: N/A | Q10: 42176 | R10: =REFUELLERS[[#This Row],[PROXIMO CAMBIO]]-$D$1 -> -3841 | S10: =IF($D$1<=REFUELLERS[[#This Row],[PROXIMO CAMBIO]],"VIGENTE","VENCIDO") -> VENCIDO | T10: SATURADOS | U10: =IFERROR(LOOKUP("SATURADOS",REFUELLERS[[#This Row],[CONDICION]],REFUELLERS[[#This Row],[CANT]]),0) -> 27 | V10: =IFERROR(LOOKUP("SATURADOS",REFUELLERS[[#This Row],[CONDICION]],REFUELLERS[[#This Row],[CANT ]]),0) -> 0
A11: =A10+1 -> 6 | B11: OEO | C11: MED | D11: INTERNATIONAL | E11: S 1900 | F11: MOV 059 | G11: GFP-522 | H11: 1989 | I11: 5000 | J11: JET A-1 | K11: Separador | L11: Velcon | M11: 3 | N11: I-63383TB | O11: 1 | P11: SO-436V | Q11: 46925 | R11: =REFUELLERS[[#This Row],[PROXIMO CAMBIO]]-$D$1 -> 908 | S11: =IF($D$1<=REFUELLERS[[#This Row],[PROXIMO CAMBIO]],"VIGENTE","VENCIDO") -> VIGENTE | U11: =IFERROR(LOOKUP("SATURADOS",REFUELLERS[[#This Row],[CONDICION]],REFUELLERS[[#This Row],[CANT]]),0) -> 0 | V11: =IFERROR(LOOKUP("SATURADOS",REFUELLERS[[#This Row],[CONDICION]],REFUELLERS[[#This Row],[CANT ]]),0) -> 0
A12: =A11+1 -> 7 | B12: ORA | C12: AXM | D12: CHEVROLET | E12: KODIAK | F12: MOV 062 | G12: LAM-566 | H12: 1996 | I12: 3850 | J12: JET A-1 | K12: Separador | L12: Facet | M12: 2 | N12: CAA28-5SB | O12: 1 | P12: SS630FE-5 | Q12: 44368 | R12: =REFUELLERS[[#This Row],[PROXIMO CAMBIO]]-$D$1 -> -1649 | S12: =IF($D$1<=REFUELLERS[[#This Row],[PROXIMO CAMBIO]],"VIGENTE","VENCIDO") -> VENCIDO | T12: SATURADOS | U12: =IFERROR(LOOKUP("SATURADOS",REFUELLERS[[#This Row],[CONDICION]],REFUELLERS[[#This Row],[CANT]]),0) -> 2 | V12: =IFERROR(LOOKUP("SATURADOS",REFUELLERS[[#This Row],[CONDICION]],REFUELLERS[[#This Row],[CANT ]]),0) -> 1
A13: =A12+1 -> 8 | B13: ORA | C13: IBE | D13: CHEVROLET | E13: NPR | F13: MOV 064 | G13: FTR-598 | H13: 2006 | I13: 2265 | J13: JET A-1 | K13: Separador | L13: Facet | M13: 2 | N13: CAA22-5SB | O13: 1 | P13: SS622FF-5 | Q13: 46559 | R13: =REFUELLERS[[#This Row],[PROXIMO CAMBIO]]-$D$1 -> 542 | S13: =IF($D$1<=REFUELLERS[[#This Row],[PROXIMO CAMBIO]],"VIGENTE","VENCIDO") -> VIGENTE | U13: =IFERROR(LOOKUP("SATURADOS",REFUELLERS[[#This Row],[CONDICION]],REFUELLERS[[#This Row],[CANT]]),0) -> 0 | V13: =IFERROR(LOOKUP("SATURADOS",REFUELLERS[[#This Row],[CONDICION]],REFUELLERS[[#This Row],[CANT ]]),0) -> 0
A14: =A13+1 -> 9 | B14: OJR | C14: CLO | D14: INTERNATIONAL | E14: 4900 | F14: MOV 065 | G14: VKK-836 | H14: 1990 | I14: 5120 | J14: JET A-1 | K14: Separador | L14: Facet | M14: 3 | N14: CAA33-5SB | O14: 1 | P14: SS436FB-5 | Q14: 46783 | R14: =REFUELLERS[[#This Row],[PROXIMO CAMBIO]]-$D$1 -> 766 | S14: =IF($D$1<=REFUELLERS[[#This Row],[PROXIMO CAMBIO]],"VIGENTE","VENCIDO") -> VIGENTE | U14: =IFERROR(LOOKUP("SATURADOS",REFUELLERS[[#This Row],[CONDICION]],REFUELLERS[[#This Row],[CANT]]),0) -> 0 | V14: =IFERROR(LOOKUP("SATURADOS",REFUELLERS[[#This Row],[CONDICION]],REFUELLERS[[#This Row],[CANT ]]),0) -> 0
A15: =A14+1 -> 10 | B15: OEO | C15: MED | D15: INTERNATIONAL | E15: 4900 | F15: MOV 067 | G15: WOW-069 | H15: 2000 | I15: 3150 | J15: JET A-1 | K15: Separador | L15: Facet | M15: 3 | N15: CAA33-3SB | O15: 1 | P15: SS436FB-5 | Q15: 46194 | R15: =REFUELLERS[[#This Row],[PROXIMO CAMBIO]]-$D$1 -> 177 | S15: =IF($D$1<=REFUELLERS[[#This Row],[PROXIMO CAMBIO]],"VIGENTE","VENCIDO") -> VIGENTE | T15: SATURADOS | U15: =IFERROR(LOOKUP("SATURADOS",REFUELLERS[[#This Row],[CONDICION]],REFUELLERS[[#This Row],[CANT]]),0) -> 3 | V15: =IFERROR(LOOKUP("SATURADOS",REFUELLERS[[#This Row],[CONDICION]],REFUELLERS[[#This Row],[CANT ]]),0) -> 1
A16: =A15+1 -> 11 | B16: OEO | C16: MED | D16: INTERNATIONAL | E16: 4900 | F16: MOV 068 | G16: WOW-071 | H16: 1990 | I16: 5000 | J16: JET A-1 | K16: Separador | L16: Facet | M16: 3 | N16: CAA33-5SB | O16: 1 | P16: SS436FB-5 | Q16: 46783 | R16: =REFUELLERS[[#This Row],[PROXIMO CAMBIO]]-$D$1 -> 766 | S16: =IF($D$1<=REFUELLERS[[#This Row],[PROXIMO CAMBIO]],"VIGENTE","VENCIDO") -> VIGENTE | T16: SATURADOS | U16: =IFERROR(LOOKUP("SATURADOS",REFUELLERS[[#This Row],[CONDICION]],REFUELLERS[[#This Row],[CANT]]),0) -> 3 | V16: =IFERROR(LOOKUP("SATURADOS",REFUELLERS[[#This Row],[CONDICION]],REFUELLERS[[#This Row],[CANT ]]),0) -> 1
A17: =A16+1 -> 12 | B17: ORA | C17: IBE | D17: CHEVROLET | E17: NPR | F17: MOV 069 | G17: SRM-773 | H17: 2007 | I17: 2325 | J17: JET A-1 | K17: Separador | L17: Facet | M17: 2 | N17: CAA22-5SB | O17: 1 | P17: SS622FB-5 | Q17: 46825 | R17: =REFUELLERS[[#This Row],[PROXIMO CAMBIO]]-$D$1 -> 808 | S17: =IF($D$1<=REFUELLERS[[#This Row],[PROXIMO CAMBIO]],"VIGENTE","VENCIDO") -> VIGENTE | U17: =IFERROR(LOOKUP("SATURADOS",REFUELLERS[[#This Row],[CONDICION]],REFUELLERS[[#This Row],[CANT]]),0) -> 0 | V17: =IFERROR(LOOKUP("SATURADOS",REFUELLERS[[#This Row],[CONDICION]],REFUELLERS[[#This Row],[CANT ]]),0) -> 0
A18: =A17+1 -> 13 | B18: ORA | C18: UIB | D18: CHEVROLET | E18: NPR | F18: MOV 071 | G18: SRM-774 | H18: 2007 | I18: 2325 | J18: JET A-1 | K18: Separador | L18: Velcon | M18: 2 | N18: I-622C5TB | O18: 1 | P18: SO-324VA5 | Q18: 46624 | R18: =REFUELLERS[[#This Row],[PROXIMO CAMBIO]]-$D$1 -> 607 | S18: =IF($D$1<=REFUELLERS[[#This Row],[PROXIMO CAMBIO]],"VIGENTE","VENCIDO") -> VIGENTE | U18: =IFERROR(LOOKUP("SATURADOS",REFUELLERS[[#This Row],[CONDICION]],REFUELLERS[[#This Row],[CANT]]),0) -> 0 | V18: =IFERROR(LOOKUP("SATURADOS",REFUELLERS[[#This Row],[CONDICION]],REFUELLERS[[#This Row],[CANT ]]),0) -> 0
A19: =A18+1 -> 14 | B19: OJR | C19: CLO | D19: CHEVROLET | E19: NKR | F19: MOV 072 | G19: SOP-688 | H19: 2009 | I19: 1450 | J19: AV Gas | K19: Monitor | L19: Facet | M19: 2 | N19: FG-0-512-2 | O19: 0 | P19: N/A | Q19: 45464 | R19: =REFUELLERS[[#This Row],[PROXIMO CAMBIO]]-$D$1 -> -553 | S19: =IF($D$1<=REFUELLERS[[#This Row],[PROXIMO CAMBIO]],"VIGENTE","VENCIDO") -> VENCIDO | T19: SATURADOS | U19: =IFERROR(LOOKUP("SATURADOS",REFUELLERS[[#This Row],[CONDICION]],REFUELLERS[[#This Row],[CANT]]),0) -> 2 | V19: =IFERROR(LOOKUP("SATURADOS",REFUELLERS[[#This Row],[CONDICION]],REFUELLERS[[#This Row],[CANT ]]),0) -> 0
A20: =A19+1 -> 15 | B20: OEO | C20: MED | D20: INTERNATIONAL | E20: DT 466 | F20: MOV 073 | G20: GFP-509 | H20: 1997 | I20: 5000 | J20: JET A-1 | K20: Separador | L20: Facet | M20: 3 | N20: CAA33-3SB | O20: 1 | P20: SO-436V | Q20: 46773 | R20: =REFUELLERS[[#This Row],[PROXIMO CAMBIO]]-$D$1 -> 756 | S20: =IF($D$1<=REFUELLERS[[#This Row],[PROXIMO CAMBIO]],"VIGENTE","VENCIDO") -> VIGENTE | T20: SATURADOS | U20: =IFERROR(LOOKUP("SATURADOS",REFUELLERS[[#This Row],[CONDICION]],REFUELLERS[[#This Row],[CANT]]),0) -> 3 | V20: =IFERROR(LOOKUP("SATURADOS",REFUELLERS[[#This Row],[CONDICION]],REFUELLERS[[#This Row],[CANT ]]),0) -> 1
A21: =A20+1 -> 16 | B21: CRC | C21: EOH | D21: CHEVROLET | E21: NKR | F21: MOV 074 | G21: SRP-464 | H21: 2010 | I21: 1585 | J21: AV Gas | K21: Cartucho | L21: Velcon | M21: 1 | N21: ACO 51201P | O21: 0 | P21: N/A | Q21: 46352 | R21: =REFUELLERS[[#This Row],[PROXIMO CAMBIO]]-$D$1 -> 335 | S21: =IF($D$1<=REFUELLERS[[#This Row],[PROXIMO CAMBIO]],"VIGENTE","VENCIDO") -> VIGENTE | U21: =IFERROR(LOOKUP("SATURADOS",REFUELLERS[[#This Row],[CONDICION]],REFUELLERS[[#This Row],[CANT]]),0) -> 0 | V21: =IFERROR(LOOKUP("SATURADOS",REFUELLERS[[#This Row],[CONDICION]],REFUELLERS[[#This Row],[CANT ]]),0) -> 0
A22: =A21+1 -> 17 | D22: FORD | E22: F 800 | F22: MOV 075 | G22: GFP-512 | H22: 1991 | I22: 4500 | J22: JET A-1 | K22: Separador | L22: Velcon | M22: 3 | N22: I-633C5TB | O22: 1 | P22: SO-436V5 | Q22: 45464 | R22: =REFUELLERS[[#This Row],[PROXIMO CAMBIO]]-$D$1 -> -553 | S22: =IF($D$1<=REFUELLERS[[#This Row],[PROXIMO CAMBIO]],"VIGENTE","VENCIDO") -> VENCIDO | T22: SATURADOS | U22: =IFERROR(LOOKUP("SATURADOS",REFUELLERS[[#This Row],[CONDICION]],REFUELLERS[[#This Row],[CANT]]),0) -> 3 | V22: =IFERROR(LOOKUP("SATURADOS",REFUELLERS[[#This Row],[CONDICION]],REFUELLERS[[#This Row],[CANT ]]),0) -> 1
A23: =A22+1 -> 18 | B23: GN | C23: BAQ | D23: CHEVROLET | E23: NPR | F23: MOV 077 | G23: SRP-605 | H23: 2010 | I23: 2500 | J23: JET A-1 | K23: Separador | L23: Facet | M23: 2 | N23: CAA22-5SB | O23: 1 | P23: SS622FB-5 | Q23: 44368 | R23: =REFUELLERS[[#This Row],[PROXIMO CAMBIO]]-$D$1 -> -1649 | S23: =IF($D$1<=REFUELLERS[[#This Row],[PROXIMO CAMBIO]],"VIGENTE","VENCIDO") -> VENCIDO | T23: SATURADOS | U23: =IFERROR(LOOKUP("SATURADOS",REFUELLERS[[#This Row],[CONDICION]],REFUELLERS[[#This Row],[CANT]]),0) -> 2 | V23: =IFERROR(LOOKUP("SATURADOS",REFUELLERS[[#This Row],[CONDICION]],REFUELLERS[[#This Row],[CANT ]]),0) -> 1
A24: =A23+1 -> 19 | B24: ORA | C24: FLA | D24: CHEVROLET | E24: NPR | F24: MOV 078 | G24: SRP-748 | H24: 2011 | I24: 2250 | J24: JET A-1 | K24: Separador | L24: Velcon | M24: 2 | N24: I-622C5TB | O24: 1 | P24: SO-623VA | Q24: 46925 | R24: =REFUELLERS[[#This Row],[PROXIMO CAMBIO]]-$D$1 -> 908 | S24: =IF($D$1<=REFUELLERS[[#This Row],[PROXIMO CAMBIO]],"VIGENTE","VENCIDO") -> VIGENTE | U24: =IFERROR(LOOKUP("SATURADOS",REFUELLERS[[#This Row],[CONDICION]],REFUELLERS[[#This Row],[CANT]]),0) -> 0 | V24: =IFERROR(LOOKUP("SATURADOS",REFUELLERS[[#This Row],[CONDICION]],REFUELLERS[[#This Row],[CANT ]]),0) -> 0
A25: =A24+1 -> 20 | B25: HC | C25: GAA | D25: CHEVROLET | E25: NKR | F25: MOV 079 | G25: SPV-738 | H25: 2011 | I25: 1615 | J25: JET A-1 | K25: Cartucho | L25: Velcon | M25: 2 | N25: ACO 51201L | O25: 0 | P25: N/A | Q25: 46341 | R25: =REFUELLERS[[#This Row],[PROXIMO CAMBIO]]-$D$1 -> 324 | S25: =IF($D$1<=REFUELLERS[[#This Row],[PROXIMO CAMBIO]],"VIGENTE","VENCIDO") -> VIGENTE | U25: =IFERROR(LOOKUP("SATURADOS",REFUELLERS[[#This Row],[CONDICION]],REFUELLERS[[#This Row],[CANT]]),0) -> 0 | V25: =IFERROR(LOOKUP("SATURADOS",REFUELLERS[[#This Row],[CONDICION]],REFUELLERS[[#This Row],[CANT ]]),0) -> 0
A26: =A25+1 -> 21 | B26: GN | C26: CZU | D26: CHEVROLET | E26: NKR | F26: MOV 080 | G26: SPV-739 | H26: 2011 | I26: 1600 | J26: JET A-1 | K26: Cartucho | L26: Velcon | M26: 2 | N26: ACO 51201R | O26: 0 | P26: N/A | Q26: 44368 | R26: =REFUELLERS[[#This Row],[PROXIMO CAMBIO]]-$D$1 -> -1649 | S26: =IF($D$1<=REFUELLERS[[#This Row],[PROXIMO CAMBIO]],"VIGENTE","VENCIDO") -> VENCIDO | T26: SATURADOS | U26: =IFERROR(LOOKUP("SATURADOS",REFUELLERS[[#This Row],[CONDICION]],REFUELLERS[[#This Row],[CANT]]),0) -> 2 | V26: =IFERROR(LOOKUP("SATURADOS",REFUELLERS[[#This Row],[CONDICION]],REFUELLERS[[#This Row],[CANT ]]),0) -> 0
A27: =A26+1 -> 22 | B27: OJR | C27: PPN | D27: FORD | E27: F 600 | F27: MOV 082 | G27: KPN-543 | H27: 1991 | I27: 1250 | J27: AV Gas | K27: Cartucho | L27: Velcon | M27: 1 | N27: ACO 51201P | O27: 0 | P27: N/A | Q27: 44368 | R27: =REFUELLERS[[#This Row],[PROXIMO CAMBIO]]-$D$1 -> -1649 | S27: =IF($D$1<=REFUELLERS[[#This Row],[PROXIMO CAMBIO]],"VIGENTE","VENCIDO") -> VENCIDO | T27: SATURADOS | U27: =IFERROR(LOOKUP("SATURADOS",REFUELLERS[[#This Row],[CONDICION]],REFUELLERS[[#This Row],[CANT]]),0) -> 1 | V27: =IFERROR(LOOKUP("SATURADOS",REFUELLERS[[#This Row],[CONDICION]],REFUELLERS[[#This Row],[CANT ]]),0) -> 0
A28: =A27+1 -> 23 | B28: HC | C28: GAA | D28: FORD | E28: F 600 | F28: MOV 083 | G28: KPN-555 | H28: 1991 | I28: 1200 | J28: AV Gas | K28: Monitor | L28: Facet | M28: 1 | N28: FG-O-609-2 | O28: 0 | P28: N/A | Q28: 46194 | R28: =REFUELLERS[[#This Row],[PROXIMO CAMBIO]]-$D$1 -> 177 | S28: =IF($D$1<=REFUELLERS[[#This Row],[PROXIMO CAMBIO]],"VIGENTE","VENCIDO") -> VIGENTE | U28: =IFERROR(LOOKUP("SATURADOS",REFUELLERS[[#This Row],[CONDICION]],REFUELLERS[[#This Row],[CANT]]),0) -> 0 | V28: =IFERROR(LOOKUP("SATURADOS",REFUELLERS[[#This Row],[CONDICION]],REFUELLERS[[#This Row],[CANT ]]),0) -> 0
A29: =A28+1 -> 24 | B29: OJR | C29: PPN | D29: CHEVROLET | E29: NQR | F29: MOV 084 | G29: SZW-246 | H29: 2012 | I29: 2500 | J29: JET A-1 | K29: Separador | L29: Facet | M29: 2 | N29: CAA22-5SB | O29: 1 | P29: SS436FB-5 | Q29: 44368 | R29: =REFUELLERS[[#This Row],[PROXIMO CAMBIO]]-$D$1 -> -1649 | S29: =IF($D$1<=REFUELLERS[[#This Row],[PROXIMO CAMBIO]],"VIGENTE","VENCIDO") -> VENCIDO | T29: SATURADOS | U29: =IFERROR(LOOKUP("SATURADOS",REFUELLERS[[#This Row],[CONDICION]],REFUELLERS[[#This Row],[CANT]]),0) -> 2 | V29: =IFERROR(LOOKUP("SATURADOS",REFUELLERS[[#This Row],[CONDICION]],REFUELLERS[[#This Row],[CANT ]]),0) -> 1
A30: =A29+1 -> 25 | B30: CRC | C30: EOH | D30: CHEVROLET | E30: NKR | F30: MOV 085 | G30: SZW-389 | H30: 2012 | I30: 2000 | J30: JET A-1 | K30: Monitor | L30: Velcon | M30: 10 | N30: CDF-230P | O30: 0 | P30: N/A | Q30: 46194 | R30: =REFUELLERS[[#This Row],[PROXIMO CAMBIO]]-$D$1 -> 177 | S30: =IF($D$1<=REFUELLERS[[#This Row],[PROXIMO CAMBIO]],"VIGENTE","VENCIDO") -> VIGENTE | U30: =IFERROR(LOOKUP("SATURADOS",REFUELLERS[[#This Row],[CONDICION]],REFUELLERS[[#This Row],[CANT]]),0) -> 0 | V30: =IFERROR(LOOKUP("SATURADOS",REFUELLERS[[#This Row],[CONDICION]],REFUELLERS[[#This Row],[CANT ]]),0) -> 0
A31: =A30+1 -> 26 | B31: OEO | C31: MED | D31: INTERNATIONAL | E31: 4700 4X2 | F31: MOV 086 | G31: WOW-093 | H31: 2012 | I31: 3000 | J31: JET A-1 | K31: Separador | L31: Facet | M31: 3 | N31: CAA33-5SB | O31: 1 | P31: SS436FB-5 | Q31: 46194 | R31: =REFUELLERS[[#This Row],[PROXIMO CAMBIO]]-$D$1 -> 177 | S31: =IF($D$1<=REFUELLERS[[#This Row],[PROXIMO CAMBIO]],"VIGENTE","VENCIDO") -> VIGENTE | U31: =IFERROR(LOOKUP("SATURADOS",REFUELLERS[[#This Row],[CONDICION]],REFUELLERS[[#This Row],[CANT]]),0) -> 0 | V31: =IFERROR(LOOKUP("SATURADOS",REFUELLERS[[#This Row],[CONDICION]],REFUELLERS[[#This Row],[CANT ]]),0) -> 0
A32: =A31+1 -> 27 | B32: OJR | C32: CLO | D32: INTERNATIONAL | E32: 4300 | F32: MOV 088 | G32: SPX-874 | H32: 2013 | I32: 3150 | J32: JET A-1 | K32: Separador | L32: Facet | M32: 3 | N32: CAA33-5SB | O32: 1 | P32: SM-436FE-5 | Q32: 44368 | R32: =REFUELLERS[[#This Row],[PROXIMO CAMBIO]]-$D$1 -> -1649 | S32: =IF($D$1<=REFUELLERS[[#This Row],[PROXIMO CAMBIO]],"VIGENTE","VENCIDO") -> VENCIDO | T32: SATURADOS | U32: =IFERROR(LOOKUP("SATURADOS",REFUELLERS[[#This Row],[CONDICION]],REFUELLERS[[#This Row],[CANT]]),0) -> 3 | V32: =IFERROR(LOOKUP("SATURADOS",REFUELLERS[[#This Row],[CONDICION]],REFUELLERS[[#This Row],[CANT ]]),0) -> 1
A33: =A32+1 -> 28 | B33: OJR | C33: CLO | D33: INTERNATIONAL | E33: 4300 | F33: MOV 089 | G33: SPY-210 | H33: 2007 | I33: 3000 | J33: JET A-1 | K33: Separador | L33: Velcon | M33: 3 | N33: I-633C5TB | O33: 1 | P33: SO-436V5 | Q33: 46827 | R33: =REFUELLERS[[#This Row],[PROXIMO CAMBIO]]-$D$1 -> 810 | S33: =IF($D$1<=REFUELLERS[[#This Row],[PROXIMO CAMBIO]],"VIGENTE","VENCIDO") -> VIGENTE | U33: =IFERROR(LOOKUP("SATURADOS",REFUELLERS[[#This Row],[CONDICION]],REFUELLERS[[#This Row],[CANT]]),0) -> 0 | V33: =IFERROR(LOOKUP("SATURADOS",REFUELLERS[[#This Row],[CONDICION]],REFUELLERS[[#This Row],[CANT ]]),0) -> 0
A34: =A33+1 -> 29 | B34: ORA | C34: AXM | D34: CHEVROLET | E34: KODIAK | F34: MOV 090 | G34: SKH-065 | H34: 1995 | I34: 2650 | J34: JET A-1 | K34: Separador | L34: Facet | M34: 3 | N34: CAA22-5SB | O34: 1 | P34: SS424FB-5 | Q34: 46825 | R34: =REFUELLERS[[#This Row],[PROXIMO CAMBIO]]-$D$1 -> 808 | S34: =IF($D$1<=REFUELLERS[[#This Row],[PROXIMO CAMBIO]],"VIGENTE","VENCIDO") -> VIGENTE | U34: =IFERROR(LOOKUP("SATURADOS",REFUELLERS[[#This Row],[CONDICION]],REFUELLERS[[#This Row],[CANT]]),0) -> 0 | V34: =IFERROR(LOOKUP("SATURADOS",REFUELLERS[[#This Row],[CONDICION]],REFUELLERS[[#This Row],[CANT ]]),0) -> 0
A35: =A34+1 -> 30 | B35: ORA | C35: PEI | D35: FORD | E35: 700 | F35: MOV 091 | G35: KPN-551 | H35: 1991 | I35: 2650 | J35: JET A-1 | K35: Separador | L35: Velcon | M35: 3 | N35: I-628C5TB | O35: 1 | P35: SO-623V5 | Q35: 46620 | R35: =REFUELLERS[[#This Row],[PROXIMO CAMBIO]]-$D$1 -> 603 | S35: =IF($D$1<=REFUELLERS[[#This Row],[PROXIMO CAMBIO]],"VIGENTE","VENCIDO") -> VIGENTE | U35: =IFERROR(LOOKUP("SATURADOS",REFUELLERS[[#This Row],[CONDICION]],REFUELLERS[[#This Row],[CANT]]),0) -> 0 | V35: =IFERROR(LOOKUP("SATURADOS",REFUELLERS[[#This Row],[CONDICION]],REFUELLERS[[#This Row],[CANT ]]),0) -> 0
A36: =A35+1 -> 31 | B36: OEO | C36: MED | D36: KENWORTH | E36: T370 | F36: MOV 100 | G36: SPN291 | H36: 2011 | I36: 6000 | J36: JET A-1 | K36: Separador | L36: Velcon | M36: 3 | N36: CAA33-5SB | O36: 1 | P36: SS436FB-5 | R36: =REFUELLERS[[#This Row],[PROXIMO CAMBIO]]-$D$1 -> -46017 | S36: =IF($D$1<=REFUELLERS[[#This Row],[PROXIMO CAMBIO]],"VIGENTE","VENCIDO") -> VENCIDO | T36: SATURADOS | U36: =IFERROR(LOOKUP("SATURADOS",REFUELLERS[[#This Row],[CONDICION]],REFUELLERS[[#This Row],[CANT]]),0) -> 3 | V36: =IFERROR(LOOKUP("SATURADOS",REFUELLERS[[#This Row],[CONDICION]],REFUELLERS[[#This Row],[CANT ]]),0) -> 1
M37: =SUBTOTAL(109,REFUELLERS[CANT]) -> 106 | O37: =SUBTOTAL(109,REFUELLERS[[CANT ]]) -> 22

Sheet  Elementos Plantas
A1: FECHA | D1: =TODAY() -> 46017 | E1: ALERTA DE VIGILANCIA 120 DIAS O NENOS
A3: PLANTAS
A4: DATOS EDSA / TERMINAL | G4: FILTRACION | M4: ESTADO
A5: # | B5: SUP | C5: COD | D5: EDSA / TERMINAL | E5: UBICACIÓN | F5: PRODUCTO | G5: FILTRACION2 | H5: MARCA | I5: CANT | J5: 1º ETAPA | K5: CANT | L5: 2º ETAPA | M5: PROXIMO CAMBIO | N5: DIAS DE VIGILANCIA | O5: ESTADO | P5: CONDICION | Q5: V 1° | R5: V 2°
A6: 1 | B6: ORA | C6: AXM | D6: ARMENIA | E6: Z. Bombas | F6: JET A-1 | G6: Separador | H6: Facet | I6: 4 | J6: CAA28-5SB | K6: 3 | L6: SS609F-5 | M6: 46528 | N6: =PLANTAS[[#This Row],[PROXIMO CAMBIO]]-$D$1 -> 511 | O6: =IF($D$1<=PLANTAS[[#This Row],[PROXIMO CAMBIO]],"VIGENTE","VENCIDO") -> VIGENTE | Q6: =IFERROR(LOOKUP("SATURADOS",PLANTAS[[#This Row],[CONDICION]],PLANTAS[[#This Row],[CANT]]),0) -> 0 | R6: =IFERROR(LOOKUP("SATURADOS",PLANTAS[[#This Row],[CONDICION]],PLANTAS[[#This Row],[CANT ]]),0) -> 0
A7: =A6+1 -> 2 | B7: ORA | C7: BUN | D7: BUENAVENTURA | E7: Gabinete | F7: JET A-1 | G7: Cartucho | H7: Velcon | I7: 1 | J7: ACO 51201L | L7: N/A | M7: 46235 | N7: =PLANTAS[[#This Row],[PROXIMO CAMBIO]]-$D$1 -> 218 | O7: =IF($D$1<=PLANTAS[[#This Row],[PROXIMO CAMBIO]],"VIGENTE","VENCIDO") -> VIGENTE | Q7: =IFERROR(LOOKUP("SATURADOS",PLANTAS[[#This Row],[CONDICION]],PLANTAS[[#This Row],[CANT]]),0) -> 0 | R7: =IFERROR(LOOKUP("SATURADOS",PLANTAS[[#This Row],[CONDICION]],PLANTAS[[#This Row],[CANT ]]),0) -> 0
A8: =A7+1 -> 3 | B8: GN | C8: CZU | D8: COROZAL | E8: Gabinete | F8: JET A-1 | G8: Cartucho | H8: Velcon | I8: 1 | J8: ACO 51201L | L8: N/A | M8: 44368 | N8: =PLANTAS[[#This Row],[PROXIMO CAMBIO]]-$D$1 -> -1649 | O8: =IF($D$1<=PLANTAS[[#This Row],[PROXIMO CAMBIO]],"VIGENTE","VENCIDO") -> VENCIDO | P8: SATURADOS | Q8: =IFERROR(LOOKUP("SATURADOS",PLANTAS[[#This Row],[CONDICION]],PLANTAS[[#This Row],[CANT]]),0) -> 1 | R8: =IFERROR(LOOKUP("SATURADOS",PLANTAS[[#This Row],[CONDICION]],PLANTAS[[#This Row],[CANT ]]),0) -> 0
A9: =A8+1 -> 4 | B9: GN | C9: CZU | D9: COROZAL | E9: Gabinete | F9: JET A-1 | G9: Cartucho | H9: Velcon | I9: 1 | J9: ACO 51201L | L9: N/A | M9: 44368 | N9: =PLANTAS[[#This Row],[PROXIMO CAMBIO]]-$D$1 -> -1649 | O9: =IF($D$1<=PLANTAS[[#This Row],[PROXIMO CAMBIO]],"VIGENTE","VENCIDO") -> VENCIDO | P9: SATURADOS | Q9: =IFERROR(LOOKUP("SATURADOS",PLANTAS[[#This Row],[CONDICION]],PLANTAS[[#This Row],[CANT]]),0) -> 1 | R9: =IFERROR(LOOKUP("SATURADOS",PLANTAS[[#This Row],[CONDICION]],PLANTAS[[#This Row],[CANT ]]),0) -> 0
A10: =A9+1 -> 5 | B10: ORA | C10: BUN | D10: BUENAVENTURA | E10: Gabinete | F10: JET A-1 | G10: Cartucho | H10: Velcon | I10: 1 | J10: ACO 51201L | L10: N/A | M10: 46235 | N10: =PLANTAS[[#This Row],[PROXIMO CAMBIO]]-$D$1 -> 218 | O10: =IF($D$1<=PLANTAS[[#This Row],[PROXIMO CAMBIO]],"VIGENTE","VENCIDO") -> VIGENTE | Q10: =IFERROR(LOOKUP("SATURADOS",PLANTAS[[#This Row],[CONDICION]],PLANTAS[[#This Row],[CANT]]),0) -> 0 | R10: =IFERROR(LOOKUP("SATURADOS",PLANTAS[[#This Row],[CONDICION]],PLANTAS[[#This Row],[CANT ]]),0) -> 0
A11: =A10+1 -> 6 | B11: ORA | C11: BUN | D11: BUENAVENTURA | E11: Z. Bombas | F11: JET A-1 | G11: Separador | H11: Velcon | I11: 2 | J11: I-628C5TB | K11: 1 | L11: SO-630PV5 | M11: 44368 | N11: =PLANTAS[[#This Row],[PROXIMO CAMBIO]]-$D$1 -> -1649 | O11: =IF($D$1<=PLANTAS[[#This Row],[PROXIMO CAMBIO]],"VIGENTE","VENCIDO") -> VENCIDO | P11: SATURADOS | Q11: =IFERROR(LOOKUP("SATURADOS",PLANTAS[[#This Row],[CONDICION]],PLANTAS[[#This Row],[CANT]]),0) -> 2 | R11: =IFERROR(LOOKUP("SATURADOS",PLANTAS[[#This Row],[CONDICION]],PLANTAS[[#This Row],[CANT ]]),0) -> 1
A12: =A11+1 -> 7 | B12: ORA | C12: FLA | D12: FLORENCIA | E12: Gabinete | F12: JET A-1 | G12: Cartucho | H12: Velcon | I12: 1 | J12: ACO 52401R | L12: N/A | M12: 44368 | N12: =PLANTAS[[#This Row],[PROXIMO CAMBIO]]-$D$1 -> -1649 | O12: =IF($D$1<=PLANTAS[[#This Row],[PROXIMO CAMBIO]],"VIGENTE","VENCIDO") -> VENCIDO | P12: SATURADOS | Q12: =IFERROR(LOOKUP("SATURADOS",PLANTAS[[#This Row],[CONDICION]],PLANTAS[[#This Row],[CANT]]),0) -> 1 | R12: =IFERROR(LOOKUP("SATURADOS",PLANTAS[[#This Row],[CONDICION]],PLANTAS[[#This Row],[CANT ]]),0) -> 0
A13: =A12+1 -> 8 | B13: ORA | C13: FLA | D13: FLORENCIA | E13: Z. Bombas | F13: JET A-1 | G13: Separador | H13: Facet | I13: 4 | J13: CAA28-5SB | K13: 2 | L13: SS609FF-5 | M13: 44369 | N13: =PLANTAS[[#This Row],[PROXIMO CAMBIO]]-$D$1 -> -1648 | O13: =IF($D$1<=PLANTAS[[#This Row],[PROXIMO CAMBIO]],"VIGENTE","VENCIDO") -> VENCIDO | P13: SATURADOS | Q13: =IFERROR(LOOKUP("SATURADOS",PLANTAS[[#This Row],[CONDICION]],PLANTAS[[#This Row],[CANT]]),0) -> 4 | R13: =IFERROR(LOOKUP("SATURADOS",PLANTAS[[#This Row],[CONDICION]],PLANTAS[[#This Row],[CANT ]]),0) -> 2
A14: =A13+1 -> 9 | B14: ORA | C14: IBE | D14: IBAGUE | E14: Z. Bombas | F14: JET A-1 | G14: Separador | H14: Facet | I14: 3 | J14: CAA14-5SB | K14: 1 | L14: SO-614FB5 | M14: 46966 | N14: =PLANTAS[[#This Row],[PROXIMO CAMBIO]]-$D$1 -> 949 | O14: =IF($D$1<=PLANTAS[[#This Row],[PROXIMO CAMBIO]],"VIGENTE","VENCIDO") -> VIGENTE | Q14: =IFERROR(LOOKUP("SATURADOS",PLANTAS[[#This Row],[CONDICION]],PLANTAS[[#This Row],[CANT]]),0) -> 0 | R14: =IFERROR(LOOKUP("SATURADOS",PLANTAS[[#This Row],[CONDICION]],PLANTAS[[#This Row],[CANT ]]),0) -> 0
A15: =A14+1 -> 10 | B15: ORA | C15: IBE | D15: IBAGUE | E15: Z. Bombas | F15: AV Gas | G15: Separador | H15: Velcon | I15: 2 | J15: CAA28-5SB | K15: 1 | L15: SS629FD-5 | M15: 44368 | N15: =PLANTAS[[#This Row],[PROXIMO CAMBIO]]-$D$1 -> -1649 | O15: =IF($D$1<=PLANTAS[[#This Row],[PROXIMO CAMBIO]],"VIGENTE","VENCIDO") -> VENCIDO | P15: SATURADOS | Q15: =IFERROR(LOOKUP("SATURADOS",PLANTAS[[#This Row],[CONDICION]],PLANTAS[[#This Row],[CANT]]),0) -> 2 | R15: =IFERROR(LOOKUP("SATURADOS",PLANTAS[[#This Row],[CONDICION]],PLANTAS[[#This Row],[CANT ]]),0) -> 1
A16: =A15+1 -> 11 | B16: ORA | C16: IBE | D16: IBAGUE | E16: Gabinete | F16: JET A-1 | G16: Cartucho | H16: Velcon | L16: N/A | Q16: =IFERROR(LOOKUP("SATURADOS",PLANTAS[[#This Row],[CONDICION]],PLANTAS[[#This Row],[CANT]]),0) -> 0 | R16: =IFERROR(LOOKUP("SATURADOS",PLANTAS[[#This Row],[CONDICION]],PLANTAS[[#This Row],[CANT ]]),0) -> 0
A17: =A16+1 -> 12 | B17: ORA | C17: IBE | D17: IBAGUE | E17: Gabinete | F17: JET A-1 | G17: Cartucho | H17: Velcon | L17: N/A | Q17: =IFERROR(LOOKUP("SATURADOS",PLANTAS[[#This Row],[CONDICION]],PLANTAS[[#This Row],[CANT]]),0) -> 0 | R17: =IFERROR(LOOKUP("SATURADOS",PLANTAS[[#This Row],[CONDICION]],PLANTAS[[#This Row],[CANT ]]),0) -> 0
A18: =A17+1 -> 13 | B18: ORA | C18: IBE | D18: IBAGUE | E18: Gabinete | F18: AV Gas | G18: Cartucho | H18: Facet | I18: 1 | J18: ACO 51201L | L18: N/A | M18: 46266 | N18: =PLANTAS[[#This Row],[PROXIMO CAMBIO]]-$D$1 -> 249 | O18: =IF($D$1<=PLANTAS[[#This Row],[PROXIMO CAMBIO]],"VIGENTE","VENCIDO") -> VIGENTE | Q18: =IFERROR(LOOKUP("SATURADOS",PLANTAS[[#This Row],[CONDICION]],PLANTAS[[#This Row],[CANT]]),0) -> 0 | R18: =IFERROR(LOOKUP("SATURADOS",PLANTAS[[#This Row],[CONDICION]],PLANTAS[[#This Row],[CANT ]]),0) -> 0
A19: =A18+1 -> 14 | B19: OEO | C19: MED | D19: RIONEGRO | E19: Z. Bombas D | F19: JET A-1 | G19: Separador | H19: Facet | I19: 5 | J19: CAA28-5SB | K19: 2 | L19: SS630FE-5 | M19: 46864 | N19: =PLANTAS[[#This Row],[PROXIMO CAMBIO]]-$D$1 -> 847 | O19: =IF($D$1<=PLANTAS[[#This Row],[PROXIMO CAMBIO]],"VIGENTE","VENCIDO") -> VIGENTE | Q19: =IFERROR(LOOKUP("SATURADOS",PLANTAS[[#This Row],[CONDICION]],PLANTAS[[#This Row],[CANT]]),0) -> 0 | R19: =IFERROR(LOOKUP("SATURADOS",PLANTAS[[#This Row],[CONDICION]],PLANTAS[[#This Row],[CANT ]]),0) -> 0
A20: =A19+1 -> 15 | B20: OJR | C20: CLO | D20: CALI | E20: Z. Bombas | F20: JET A-1 | G20: Separador | H20: Facet | I20: 4 | J20: CAA28-5SB | K20: 3 | L20: SS609FE-5 | M20: 46712 | N20: =PLANTAS[[#This Row],[PROXIMO CAMBIO]]-$D$1 -> 695 | O20: =IF($D$1<=PLANTAS[[#This Row],[PROXIMO CAMBIO]],"VIGENTE","VENCIDO") -> VIGENTE | Q20: =IFERROR(LOOKUP("SATURADOS",PLANTAS[[#This Row],[CONDICION]],PLANTAS[[#This Row],[CANT]]),0) -> 0 | R20: =IFERROR(LOOKUP("SATURADOS",PLANTAS[[#This Row],[CONDICION]],PLANTAS[[#This Row],[CANT ]]),0) -> 0
A21: =A20+1 -> 16 | B21: ORA | C21: MZL | D21: MANIZALES | E21: Gabinete | F21: JET A-1 | G21: Cartucho | H21: Velcon | I21: 1 | J21: ACO 51201L | L21: N/A | M21: 44368 | N21: =PLANTAS[[#This Row],[PROXIMO CAMBIO]]-$D$1 -> -1649 | O21: =IF($D$1<=PLANTAS[[#This Row],[PROXIMO CAMBIO]],"VIGENTE","VENCIDO") -> VENCIDO | P21: SATURADOS | Q21: =IFERROR(LOOKUP("SATURADOS",PLANTAS[[#This Row],[CONDICION]],PLANTAS[[#This Row],[CANT]]),0) -> 1 | R21: =IFERROR(LOOKUP("SATURADOS",PLANTAS[[#This Row],[CONDICION]],PLANTAS[[#This Row],[CANT ]]),0) -> 0
A22: =A21+1 -> 17 | B22: ORA | C22: MZL | D22: MANIZALES | E22: Gabinete | F22: JET A-1 | G22: Cartucho | H22: Velcon | I22: 1 | J22: ACO 51201L | L22: N/A | M22: 44368 | N22: =PLANTAS[[#This Row],[PROXIMO CAMBIO]]-$D$1 -> -1649 | O22: =IF($D$1<=PLANTAS[[#This Row],[PROXIMO CAMBIO]],"VIGENTE","VENCIDO") -> VENCIDO | P22: SATURADOS | Q22: =IFERROR(LOOKUP("SATURADOS",PLANTAS[[#This Row],[CONDICION]],PLANTAS[[#This Row],[CANT]]),0) -> 1 | R22: =IFERROR(LOOKUP("SATURADOS",PLANTAS[[#This Row],[CONDICION]],PLANTAS[[#This Row],[CANT ]]),0) -> 0
A23: =A22+1 -> 18 | B23: ORA | C23: MZL | D23: MANIZALES | E23: Z. Bombas | F23: JET A-1 | G23: Separador | H23: Facet | I23: 3 | J23: CAA14-5SB | K23: 1 | L23: SS614FB-5 | M23: 46998 | N23: =PLANTAS[[#This Row],[PROXIMO CAMBIO]]-$D$1 -> 981 | O23: =IF($D$1<=PLANTAS[[#This Row],[PROXIMO CAMBIO]],"VIGENTE","VENCIDO") -> VIGENTE | Q23: =IFERROR(LOOKUP("SATURADOS",PLANTAS[[#This Row],[CONDICION]],PLANTAS[[#This Row],[CANT]]),0) -> 0 | R23: =IFERROR(LOOKUP("SATURADOS",PLANTAS[[#This Row],[CONDICION]],PLANTAS[[#This Row],[CANT ]]),0) -> 0
A24: =A23+1 -> 19 | B24: OEO | C24: MED | D24: RIONEGRO | E24: Z. Bombas R | F24: JET A-1 | G24: Separador | H24: Facet | I24: 5 | J24: CAA28-5SB | K24: 3 | L24: SS609FB-5 | M24: 46864 | N24: =PLANTAS[[#This Row],[PROXIMO CAMBIO]]-$D$1 -> 847 | O24: =IF($D$1<=PLANTAS[[#This Row],[PROXIMO CAMBIO]],"VIGENTE","VENCIDO") -> VIGENTE | Q24: =IFERROR(LOOKUP("SATURADOS",PLANTAS[[#This Row],[CONDICION]],PLANTAS[[#This Row],[CANT]]),0) -> 0 | R24: =IFERROR(LOOKUP("SATURADOS",PLANTAS[[#This Row],[CONDICION]],PLANTAS[[#This Row],[CANT ]]),0) -> 0
A25: =A24+1 -> 20 | B25: OEO | C25: MED | D25: RIONEGRO | E25: Z. Bombas R | F25: JET A-1 | G25: Micronico | H25: Facet | I25: 6 | J25: FO614-PL5 | L25: N/A | M25: 46773 | N25: =PLANTAS[[#This Row],[PROXIMO CAMBIO]]-$D$1 -> 756 | O25: =IF($D$1<=PLANTAS[[#This Row],[PROXIMO CAMBIO]],"VIGENTE","VENCIDO") -> VIGENTE | Q25: =IFERROR(LOOKUP("SATURADOS",PLANTAS[[#This Row],[CONDICION]],PLANTAS[[#This Row],[CANT]]),0) -> 0 | R25: =IFERROR(LOOKUP("SATURADOS",PLANTAS[[#This Row],[CONDICION]],PLANTAS[[#This Row],[CANT ]]),0) -> 0
A26: =A25+1 -> 21 | B26: GN | C26: CZU | D26: COROZAL | E26: Z. Bombas | F26: JET A-1 | G26: Separador | H26: Facet | I26: 4 | J26: CAA28-5SB | K26: 2 | L26: SS630FE-5 | M26: 44429 | N26: =PLANTAS[[#This Row],[PROXIMO CAMBIO]]-$D$1 -> -1588 | O26: =IF($D$1<=PLANTAS[[#This Row],[PROXIMO CAMBIO]],"VIGENTE","VENCIDO") -> VENCIDO | P26: SATURADOS | Q26: =IFERROR(LOOKUP("SATURADOS",PLANTAS[[#This Row],[CONDICION]],PLANTAS[[#This Row],[CANT]]),0) -> 4 | R26: =IFERROR(LOOKUP("SATURADOS",PLANTAS[[#This Row],[CONDICION]],PLANTAS[[#This Row],[CANT ]]),0) -> 2
A27: =A26+1 -> 22 | B27: GN | C27: BAQ | D27: BARRAQUILLA | E27: Z. Bombas | F27: JET A-1 | G27: Separador | H27: Facet | I27: 4 | J27: CAA28-5SB | K27: 3 | L27: SS609FE-5 | M27: 44337 | N27: =PLANTAS[[#This Row],[PROXIMO CAMBIO]]-$D$1 -> -1680 | O27: =IF($D$1<=PLANTAS[[#This Row],[PROXIMO CAMBIO]],"VIGENTE","VENCIDO") -> VENCIDO | P27: SATURADOS | Q27: =IFERROR(LOOKUP("SATURADOS",PLANTAS[[#This Row],[CONDICION]],PLANTAS[[#This Row],[CANT]]),0) -> 4 | R27: =IFERROR(LOOKUP("SATURADOS",PLANTAS[[#This Row],[CONDICION]],PLANTAS[[#This Row],[CANT ]]),0) -> 3
A28: =A27+1 -> 23 | B28: HC | C28: GAA | D28: GUAYMARAL | E28: Gabinete | F28: JET A-1 | G28: Cartucho | H28: Velcon | I28: 1 | J28: FG-O-512-2 | L28: N/A | M28: 46167 | N28: =PLANTAS[[#This Row],[PROXIMO CAMBIO]]-$D$1 -> 150 | O28: =IF($D$1<=PLANTAS[[#This Row],[PROXIMO CAMBIO]],"VIGENTE","VENCIDO") -> VIGENTE | Q28: =IFERROR(LOOKUP("SATURADOS",PLANTAS[[#This Row],[CONDICION]],PLANTAS[[#This Row],[CANT]]),0) -> 0 | R28: =IFERROR(LOOKUP("SATURADOS",PLANTAS[[#This Row],[CONDICION]],PLANTAS[[#This Row],[CANT ]]),0) -> 0
A29: =A28+1 -> 24 | B29: HC | C29: GAA | D29: GUAYMARAL | E29: Gabinete | F29: AV Gas | G29: Cartucho | H29: Velcon | I29: 2 | J29: FG-O-609-2 | L29: N/A | M29: 46167 | N29: =PLANTAS[[#This Row],[PROXIMO CAMBIO]]-$D$1 -> 150 | O29: =IF($D$1<=PLANTAS[[#This Row],[PROXIMO CAMBIO]],"VIGENTE","VENCIDO") -> VIGENTE | Q29: =IFERROR(LOOKUP("SATURADOS",PLANTAS[[#This Row],[CONDICION]],PLANTAS[[#This Row],[CANT]]),0) -> 0 | R29: =IFERROR(LOOKUP("SATURADOS",PLANTAS[[#This Row],[CONDICION]],PLANTAS[[#This Row],[CANT ]]),0) -> 0
A30: =A29+1 -> 25 | B30: OJR | C30: CLO | D30: CALI | E30: Z. Bombas | F30: AV Gas | G30: Separador | H30: Velcon | I30: 2 | J30: I-62287TB | K30: 1 | L30: SO-609C | M30: 44368 | N30: =PLANTAS[[#This Row],[PROXIMO CAMBIO]]-$D$1 -> -1649 | O30: =IF($D$1<=PLANTAS[[#This Row],[PROXIMO CAMBIO]],"VIGENTE","VENCIDO") -> VENCIDO | P30: SATURADOS | Q30: =IFERROR(LOOKUP("SATURADOS",PLANTAS[[#This Row],[CONDICION]],PLANTAS[[#This Row],[CANT]]),0) -> 2 | R30: =IFERROR(LOOKUP("SATURADOS",PLANTAS[[#This Row],[CONDICION]],PLANTAS[[#This Row],[CANT ]]),0) -> 1
A31: =A30+1 -> 26 | B31: HC | C31: GAA | D31: GUAYMARAL | E31: Z. Bombas | F31: AV Gas | G31: Separador | H31: Velcon | I31: 2 | J31: I-61487TB | K31: 1 | L31: SS622FB-5 | M31: 43272 | N31: =PLANTAS[[#This Row],[PROXIMO CAMBIO]]-$D$1 -> -2745 | O31: =IF($D$1<=PLANTAS[[#This Row],[PROXIMO CAMBIO]],"VIGENTE","VENCIDO") -> VENCIDO | P31: SATURADOS | Q31: =IFERROR(LOOKUP("SATURADOS",PLANTAS[[#This Row],[CONDICION]],PLANTAS[[#This Row],[CANT]]),0) -> 2 | R31: =IFERROR(LOOKUP("SATURADOS",PLANTAS[[#This Row],[CONDICION]],PLANTAS[[#This Row],[CANT ]]),0) -> 1
A32: =A31+1 -> 27 | B32: GN | C32: BAQ | D32: BARRAQUILLA | E32: Z. Bombas | F32: AV Gas | G32: Separador | H32: Velcon | I32: 2 | J32: I-62287TB | K32: 1 | L32: SO-629C | M32: 44368 | N32: =PLANTAS[[#This Row],[PROXIMO CAMBIO]]-$D$1 -> -1649 | O32: =IF($D$1<=PLANTAS[[#This Row],[PROXIMO CAMBIO]],"VIGENTE","VENCIDO") -> VENCIDO | P32: SATURADOS | Q32: =IFERROR(LOOKUP("SATURADOS",PLANTAS[[#This Row],[CONDICION]],PLANTAS[[#This Row],[CANT]]),0) -> 2 | R32: =IFERROR(LOOKUP("SATURADOS",PLANTAS[[#This Row],[CONDICION]],PLANTAS[[#This Row],[CANT ]]),0) -> 1
A33: =A32+1 -> 28 | B33: HC | C33: GAA | D33: GUAYMARAL | E33: Z. Bombas | F33: JET A-1 | G33: Separador | H33: Facet | I33: 1 | J33: CAA22-5SB | K33: 1 | L33: SS622FB-5 | M33: 43278 | N33: =PLANTAS[[#This Row],[PROXIMO CAMBIO]]-$D$1 -> -2739 | O33: =IF($D$1<=PLANTAS[[#This Row],[PROXIMO CAMBIO]],"VIGENTE","VENCIDO") -> VENCIDO | P33: SATURADOS | Q33: =IFERROR(LOOKUP("SATURADOS",PLANTAS[[#This Row],[CONDICION]],PLANTAS[[#This Row],[CANT]]),0) -> 1 | R33: =IFERROR(LOOKUP("SATURADOS",PLANTAS[[#This Row],[CONDICION]],PLANTAS[[#This Row],[CANT ]]),0) -> 1
A34: =A33+1 -> 29 | B34: ORA | C34: PEI | D34: PEREIRA | E34: Z. Bombas | F34: JET A-1 | G34: Separador | H34: Facet | I34: 3 | J34: CAA28-5SB | K34: 4 | L34: SS609FE-5 | M34: 46439 | N34: =PLANTAS[[#This Row],[PROXIMO CAMBIO]]-$D$1 -> 422 | O34: =IF($D$1<=PLANTAS[[#This Row],[PROXIMO CAMBIO]],"VIGENTE","VENCIDO") -> VIGENTE | Q34: =IFERROR(LOOKUP("SATURADOS",PLANTAS[[#This Row],[CONDICION]],PLANTAS[[#This Row],[CANT]]),0) -> 0 | R34: =IFERROR(LOOKUP("SATURADOS",PLANTAS[[#This Row],[CONDICION]],PLANTAS[[#This Row],[CANT ]]),0) -> 0
A35: =A34+1 -> 30 | B35: CRC | C35: EOH | D35: MEDELLIN | E35: Z. Bombas | F35: AV Gas | G35: Separador | H35: Velcon | I35: 2 | J35: I-62887TB | K35: 1 | L35: SO-629C | M35: 46774 | N35: =PLANTAS[[#This Row],[PROXIMO CAMBIO]]-$D$1 -> 757 | O35: =IF($D$1<=PLANTAS[[#This Row],[PROXIMO CAMBIO]],"VIGENTE","VENCIDO") -> VIGENTE | Q35: =IFERROR(LOOKUP("SATURADOS",PLANTAS[[#This Row],[CONDICION]],PLANTAS[[#This Row],[CANT]]),0) -> 0 | R35: =IFERROR(LOOKUP("SATURADOS",PLANTAS[[#This Row],[CONDICION]],PLANTAS[[#This Row],[CANT ]]),0) -> 0
A36: =A35+1 -> 31 | B36: CRC | C36: EOH | D36: MEDELLIN | E36: Z. Bombas | F36: JET A-1 | G36: Separador | H36: Facet | I36: 2 | J36: CAA28-5SB | K36: 1 | L36: SS929FD-5 | M36: 46774 | N36: =PLANTAS[[#This Row],[PROXIMO CAMBIO]]-$D$1 -> 757 | O36: =IF($D$1<=PLANTAS[[#This Row],[PROXIMO CAMBIO]],"VIGENTE","VENCIDO") -> VIGENTE | Q36: =IFERROR(LOOKUP("SATURADOS",PLANTAS[[#This Row],[CONDICION]],PLANTAS[[#This Row],[CANT]]),0) -> 0 | R36: =IFERROR(LOOKUP("SATURADOS",PLANTAS[[#This Row],[CONDICION]],PLANTAS[[#This Row],[CANT ]]),0) -> 0
A37: =A36+1 -> 32 | B37: ORA | C37: UIB | D37: QUIBDO | E37: Gabinete | F37: AV Gas | G37: Cartucho | H37: Velcon | I37: 1 | J37: ACO 51201L | L37: N/A | M37: 46143 | N37: =PLANTAS[[#This Row],[PROXIMO CAMBIO]]-$D$1 -> 126 | O37: =IF($D$1<=PLANTAS[[#This Row],[PROXIMO CAMBIO]],"VIGENTE","VENCIDO") -> VIGENTE | Q37: =IFERROR(LOOKUP("SATURADOS",PLANTAS[[#This Row],[CONDICION]],PLANTAS[[#This Row],[CANT]]),0) -> 0 | R37: =IFERROR(LOOKUP("SATURADOS",PLANTAS[[#This Row],[CONDICION]],PLANTAS[[#This Row],[CANT ]]),0) -> 0
A38: =A37+1 -> 33 | B38: OJR | C38: PPN | D38: POPAYAN | E38: Z. Bombas | F38: JET A-1 | G38: Separador | H38: Velcon | I38: 2 | J38: I-628C5TB | K38: 2 | L38: SO-609V5 | M38: 44248 | N38: =PLANTAS[[#This Row],[PROXIMO CAMBIO]]-$D$1 -> -1769 | O38: =IF($D$1<=PLANTAS[[#This Row],[PROXIMO CAMBIO]],"VIGENTE","VENCIDO") -> VENCIDO | P38: SATURADOS | Q38: =IFERROR(LOOKUP("SATURADOS",PLANTAS[[#This Row],[CONDICION]],PLANTAS[[#This Row],[CANT]]),0) -> 2 | R38: =IFERROR(LOOKUP("SATURADOS",PLANTAS[[#This Row],[CONDICION]],PLANTAS[[#This Row],[CANT ]]),0) -> 2
A39: =A38+1 -> 34 | B39: ORA | C39: UIB | D39: QUIBDO | E39: Gabinete | F39: JET A-1 | G39: Cartucho | H39: Velcon | Q39: =IFERROR(LOOKUP("SATURADOS",PLANTAS[[#This Row],[CONDICION]],PLANTAS[[#This Row],[CANT]]),0) -> 0 | R39: =IFERROR(LOOKUP("SATURADOS",PLANTAS[[#This Row],[CONDICION]],PLANTAS[[#This Row],[CANT ]]),0) -> 0
A40: =A39+1 -> 35 | B40: ORA | C40: UIB | D40: QUIBDO | E40: Gabinete | F40: JET A-1 | G40: Cartucho | H40: Velcon | Q40: =IFERROR(LOOKUP("SATURADOS",PLANTAS[[#This Row],[CONDICION]],PLANTAS[[#This Row],[CANT]]),0) -> 0 | R40: =IFERROR(LOOKUP("SATURADOS",PLANTAS[[#This Row],[CONDICION]],PLANTAS[[#This Row],[CANT ]]),0) -> 0
A41: =A40+1 -> 36 | B41: ORA | C41: UIB | D41: QUIBDO | E41: Z. Bombas | F41: JET A-1 | G41: Separador | H41: Velcon | I41: 2 | J41: I-622C5TB | K41: 1 | L41: SO-623VA5 | M41: 46624 | N41: =PLANTAS[[#This Row],[PROXIMO CAMBIO]]-$D$1 -> 607 | O41: =IF($D$1<=PLANTAS[[#This Row],[PROXIMO CAMBIO]],"VIGENTE","VENCIDO") -> VIGENTE | Q41: =IFERROR(LOOKUP("SATURADOS",PLANTAS[[#This Row],[CONDICION]],PLANTAS[[#This Row],[CANT]]),0) -> 0 | R41: =IFERROR(LOOKUP("SATURADOS",PLANTAS[[#This Row],[CONDICION]],PLANTAS[[#This Row],[CANT ]]),0) -> 0
...

Sheet RES R+P
A1: ELEMETOS FILTRNTES PARA CAMBIO
A3: Los valores aquí prestados deben ser actualizados, y se debe incluir el valor de importación y nacionalización que puede ser equivalente al 25% del costo.
A5: FECHA | C5: =TODAY() -> 46017 | E5: #VALUE! | F5: {=_FV(E5,"Precio")} -> 3693.25
H7: REMPLAZO ELEMENTOS | K7: =D12+K12 -> 71 | L7: =E12+L12 -> 12178.39 | M7: =F12+M12 -> 44977839
H8: IMPOR Y NACIONALIZA | K8: 0.25 | L8: =L7*K8 -> 3044.5975 | M8: =L8*F5 -> 11244460
H9: TOTAL REFUELLERS | L9: =SUM(L7:L8) -> 15222.987 | M9: =SUM(M7:M8) -> 56222299
A11: REFUELLERS | H11: REFUELLERS
A12: TOTALES | C12: =SUBTOTAL(109,Tabla186[CANT ISTA]) -> 106 | D12: =SUBTOTAL(109,Tabla186[PARA CAMB]) -> 61 | E12: =SUBTOTAL(109,E14:E28) -> 9617.39 | F12: =SUBTOTAL(109,F14:F28) -> 35519426 | H12: TOTALES | J12: =SUM(Tabla1869[CANT ISTA]) -> 22 | K12: =SUBTOTAL(109,Tabla1869[PARA CAMB]) -> 10 | L12: =SUBTOTAL(109,L14:L24) -> 2561 | M12: =SUBTOTAL(109,M14:M24) -> 9458413.2
A13: # | B13: 1º ETAPA | C13: CANT ISTA | D13: PARA CAMB | E13: DÓLAR | F13: PESOS | H13: # | I13: 2º ETAPA | J13: CANT ISTA | K13: PARA CAMB | L13: DÓLAR | M13: PESOS
A14: 1 | B14: ACO 51201L | C14: =SUMIF(REFUELLERS[1º ETAPA],Tabla186[[#This Row],[1º ETAPA]],REFUELLERS[CANT]) -> 2 | D14: =SUMIF(REFUELLERS[1º ETAPA],Tabla186[[#This Row],[1º ETAPA]],REFUELLERS[V 1°]) -> 0 | E14: =IF(D14=0,"0",(IFERROR(LOOKUP(B14,Costos!$B$5:$B$100,Costos!$C$5:$C$100),0)))*Tabla186[[#This Row],[PARA CAMB]] -> 0 | F14: =Tabla186[[#This Row],[DÓLAR]]*$F$5 -> 0 | H14: 1 | I14: SM-436FE-5 | J14: =SUMIF(REFUELLERS[2º ETAPA],Tabla1869[[#This Row],[2º ETAPA]],REFUELLERS[[CANT ]]) -> 1 | K14: =SUMIF(REFUELLERS[2º ETAPA],Tabla1869[[#This Row],[2º ETAPA]],REFUELLERS[V 2°]) -> 1 | L14: =IF(K14=0,"0",(IFERROR(LOOKUP(I14,Costos!$B$5:$B$100,Costos!$C$5:$C$100),0)))*Tabla1869[[#This Row],[PARA CAMB]] -> 256.1 | M14: =Tabla1869[[#This Row],[DÓLAR]]*$F$5 -> 945841.33
A15: =A14+1 -> 2 | B15: ACO 51201P | C15: =SUMIF(REFUELLERS[1º ETAPA],Tabla186[[#This Row],[1º ETAPA]],REFUELLERS[CANT]) -> 2 | D15: =SUMIF(REFUELLERS[1º ETAPA],Tabla186[[#This Row],[1º ETAPA]],REFUELLERS[V 1°]) -> 1 | E15: =IF(D15=0,"0",(IFERROR(LOOKUP(B15,Costos!$B$5:$B$100,Costos!$C$5:$C$100),0)))*Tabla186[[#This Row],[PARA CAMB]] -> 314 | F15: =Tabla186[[#This Row],[DÓLAR]]*$F$5 -> 1159680.5 | H15: =H14+1 -> 2 | I15: SO-324VA5 | J15: =SUMIF(REFUELLERS[2º ETAPA],Tabla1869[[#This Row],[2º ETAPA]],REFUELLERS[[CANT ]]) -> 1 | K15: =SUMIF(REFUELLERS[2º ETAPA],Tabla1869[[#This Row],[2º ETAPA]],REFUELLERS[V 2°]) -> 0 | L15: =IF(K15=0,"0",(IFERROR(LOOKUP(I15,Costos!$B$5:$B$100,Costos!$C$5:$C$100),0)))*Tabla1869[[#This Row],[PARA CAMB]] -> 0 | M15: =Tabla1869[[#This Row],[DÓLAR]]*$F$5 -> 0
A16: =A15+1 -> 3 | B16: ACO 51201R | C16: =SUMIF(REFUELLERS[1º ETAPA],Tabla186[[#This Row],[1º ETAPA]],REFUELLERS[CANT]) -> 4 | D16: =SUMIF(REFUELLERS[1º ETAPA],Tabla186[[#This Row],[1º ETAPA]],REFUELLERS[V 1°]) -> 4 | E16: =IF(D16=0,"0",(IFERROR(LOOKUP(B16,Costos!$B$5:$B$100,Costos!$C$5:$C$100),0)))*Tabla186[[#This Row],[PARA CAMB]] -> 1256 | F16: =Tabla186[[#This Row],[DÓLAR]]*$F$5 -> 4638722 | H16: =H15+1 -> 3 | I16: SO-436V | J16: =SUMIF(REFUELLERS[2º ETAPA],Tabla1869[[#This Row],[2º ETAPA]],REFUELLERS[[CANT ]]) -> 3 | K16: =SUMIF(REFUELLERS[2º ETAPA],Tabla1869[[#This Row],[2º ETAPA]],REFUELLERS[V 2°]) -> 1 | L16: =IF(K16=0,"0",(IFERROR(LOOKUP(I16,Costos!$B$5:$B$100,Costos!$C$5:$C$100),0)))*Tabla1869[[#This Row],[PARA CAMB]] -> 256.1 | M16: =Tabla1869[[#This Row],[DÓLAR]]*$F$5 -> 945841.33
A17: =A16+1 -> 4 | B17: CAA22-5SB | C17: =SUMIF(REFUELLERS[1º ETAPA],Tabla186[[#This Row],[1º ETAPA]],REFUELLERS[CANT]) -> 11 | D17: =SUMIF(REFUELLERS[1º ETAPA],Tabla186[[#This Row],[1º ETAPA]],REFUELLERS[V 1°]) -> 4 | E17: =IF(D17=0,"0",(IFERROR(LOOKUP(B17,Costos!$B$5:$B$100,Costos!$C$5:$C$100),0)))*Tabla186[[#This Row],[PARA CAMB]] -> 403.68 | F17: =Tabla186[[#This Row],[DÓLAR]]*$F$5 -> 1490891.2 | H17: =H16+1 -> 4 | I17: SO-436V5 | J17: =SUMIF(REFUELLERS[2º ETAPA],Tabla1869[[#This Row],[2º ETAPA]],REFUELLERS[[CANT ]]) -> 2 | K17: =SUMIF(REFUELLERS[2º ETAPA],Tabla1869[[#This Row],[2º ETAPA]],REFUELLERS[V 2°]) -> 1 | L17: =IF(K17=0,"0",(IFERROR(LOOKUP(I17,Costos!$B$5:$B$100,Costos!$C$5:$C$100),0)))*Tabla1869[[#This Row],[PARA CAMB]] -> 256.1 | M17: =Tabla1869[[#This Row],[DÓLAR]]*$F$5 -> 945841.33
A18: =A17+1 -> 5 | B18: CAA28-5SB | C18: =SUMIF(REFUELLERS[1º ETAPA],Tabla186[[#This Row],[1º ETAPA]],REFUELLERS[CANT]) -> 2 | D18: =SUMIF(REFUELLERS[1º ETAPA],Tabla186[[#This Row],[1º ETAPA]],REFUELLERS[V 1°]) -> 2 | E18: =IF(D18=0,"0",(IFERROR(LOOKUP(B18,Costos!$B$5:$B$100,Costos!$C$5:$C$100),0)))*Tabla186[[#This Row],[PARA CAMB]] -> 405.18 | F18: =Tabla186[[#This Row],[DÓLAR]]*$F$5 -> 1496431 | H18: =H17+1 -> 5 | I18: SO-623V5 | J18: =SUMIF(REFUELLERS[2º ETAPA],Tabla1869[[#This Row],[2º ETAPA]],REFUELLERS[[CANT ]]) -> 1 | K18: =SUMIF(REFUELLERS[2º ETAPA],Tabla1869[[#This Row],[2º ETAPA]],REFUELLERS[V 2°]) -> 0 | L18: =IF(K18=0,"0",(IFERROR(LOOKUP(I18,Costos!$B$5:$B$100,Costos!$C$5:$C$100),0)))*Tabla1869[[#This Row],[PARA CAMB]] -> 0 | M18: =Tabla1869[[#This Row],[DÓLAR]]*$F$5 -> 0
A19: =A18+1 -> 6 | B19: CAA33-3SB | C19: =SUMIF(REFUELLERS[1º ETAPA],Tabla186[[#This Row],[1º ETAPA]],REFUELLERS[CANT]) -> 6 | D19: =SUMIF(REFUELLERS[1º ETAPA],Tabla186[[#This Row],[1º ETAPA]],REFUELLERS[V 1°]) -> 6 | E19: =IF(D19=0,"0",(IFERROR(LOOKUP(B19,Costos!$B$5:$B$100,Costos!$C$5:$C$100),0)))*Tabla186[[#This Row],[PARA CAMB]] -> 1215.54 | F19: =Tabla186[[#This Row],[DÓLAR]]*$F$5 -> 4489293.1 | H19: =H18+1 -> 6 | I19: SO-623VA | J19: =SUMIF(REFUELLERS[2º ETAPA],Tabla1869[[#This Row],[2º ETAPA]],REFUELLERS[[CANT ]]) -> 1 | K19: =SUMIF(REFUELLERS[2º ETAPA],Tabla1869[[#This Row],[2º ETAPA]],REFUELLERS[V 2°]) -> 0 | L19: =IF(K19=0,"0",(IFERROR(LOOKUP(I19,Costos!$B$5:$B$100,Costos!$C$5:$C$100),0)))*Tabla1869[[#This Row],[PARA CAMB]] -> 0 | M19: =Tabla1869[[#This Row],[DÓLAR]]*$F$5 -> 0
A20: =A19+1 -> 7 | B20: CAA33-5SB | C20: =SUMIF(REFUELLERS[1º ETAPA],Tabla186[[#This Row],[1º ETAPA]],REFUELLERS[CANT]) -> 21 | D20: =SUMIF(REFUELLERS[1º ETAPA],Tabla186[[#This Row],[1º ETAPA]],REFUELLERS[V 1°]) -> 12 | E20: =IF(D20=0,"0",(IFERROR(LOOKUP(B20,Costos!$B$5:$B$100,Costos!$C$5:$C$100),0)))*Tabla186[[#This Row],[PARA CAMB]] -> 3113.4 | F20: =Tabla186[[#This Row],[DÓLAR]]*$F$5 -> 11498565 | H20: =H19+1 -> 7 | I20: SS424FB-5 | J20: =SUMIF(REFUELLERS[2º ETAPA],Tabla1869[[#This Row],[2º ETAPA]],REFUELLERS[[CANT ]]) -> 1 | K20: =SUMIF(REFUELLERS[2º ETAPA],Tabla1869[[#This Row],[2º ETAPA]],REFUELLERS[V 2°]) -> 0 | L20: =IF(K20=0,"0",(IFERROR(LOOKUP(I20,Costos!$B$5:$B$100,Costos!$C$5:$C$100),0)))*Tabla1869[[#This Row],[PARA CAMB]] -> 0 | M20: =Tabla1869[[#This Row],[DÓLAR]]*$F$5 -> 0
A21: =A20+1 -> 8 | B21: CDF-230P | C21: =SUMIF(REFUELLERS[1º ETAPA],Tabla186[[#This Row],[1º ETAPA]],REFUELLERS[CANT]) -> 10 | D21: =SUMIF(REFUELLERS[1º ETAPA],Tabla186[[#This Row],[1º ETAPA]],REFUELLERS[V 1°]) -> 0 | E21: =IF(D21=0,"0",(IFERROR(LOOKUP(B21,Costos!$B$5:$B$100,Costos!$C$5:$C$100),0)))*Tabla186[[#This Row],[PARA CAMB]] -> 0 | F21: =Tabla186[[#This Row],[DÓLAR]]*$F$5 -> 0 | H21: =H20+1 -> 8 | I21: SS436FB-5 | J21: =SUMIF(REFUELLERS[2º ETAPA],Tabla1869[[#This Row],[2º ETAPA]],REFUELLERS[[CANT ]]) -> 8 | K21: =SUMIF(REFUELLERS[2º ETAPA],Tabla1869[[#This Row],[2º ETAPA]],REFUELLERS[V 2°]) -> 5 | L21: =IF(K21=0,"0",(IFERROR(LOOKUP(I21,Costos!$B$5:$B$100,Costos!$C$5:$C$100),0)))*Tabla1869[[#This Row],[PARA CAMB]] -> 1280.5 | M21: =Tabla1869[[#This Row],[DÓLAR]]*$F$5 -> 4729206.6
A22: =A21+1 -> 9 | B22: FG-0-512-2 | C22: =SUMIF(REFUELLERS[1º ETAPA],Tabla186[[#This Row],[1º ETAPA]],REFUELLERS[CANT]) -> 2 | D22: =SUMIF(REFUELLERS[1º ETAPA],Tabla186[[#This Row],[1º ETAPA]],REFUELLERS[V 1°]) -> 2 | E22: =IF(D22=0,"0",(IFERROR(LOOKUP(B22,Costos!$B$5:$B$100,Costos!$C$5:$C$100),0)))*Tabla186[[#This Row],[PARA CAMB]] -> 311.5 | F22: =Tabla186[[#This Row],[DÓLAR]]*$F$5 -> 1150447.4 | H22: =H21+1 -> 9 | I22: SS622FB-5 | J22: =SUMIF(REFUELLERS[2º ETAPA],Tabla1869[[#This Row],[2º ETAPA]],REFUELLERS[[CANT ]]) -> 2 | K22: =SUMIF(REFUELLERS[2º ETAPA],Tabla1869[[#This Row],[2º ETAPA]],REFUELLERS[V 2°]) -> 1 | L22: =IF(K22=0,"0",(IFERROR(LOOKUP(I22,Costos!$B$5:$B$100,Costos!$C$5:$C$100),0)))*Tabla1869[[#This Row],[PARA CAMB]] -> 256.1 | M22: =Tabla1869[[#This Row],[DÓLAR]]*$F$5 -> 945841.33
A23: =A22+1 -> 10 | B23: FG-230-7 | C23: =SUMIF(REFUELLERS[1º ETAPA],Tabla186[[#This Row],[1º ETAPA]],REFUELLERS[CANT]) -> 27 | D23: =SUMIF(REFUELLERS[1º ETAPA],Tabla186[[#This Row],[1º ETAPA]],REFUELLERS[V 1°]) -> 27 | E23: =IF(D23=0,"0",(IFERROR(LOOKUP(B23,Costos!$B$5:$B$100,Costos!$C$5:$C$100),0)))*Tabla186[[#This Row],[PARA CAMB]] -> 1829.79 | F23: =Tabla186[[#This Row],[DÓLAR]]*$F$5 -> 6757871.9 | H23: =H22+1 -> 10 | I23: SS622FF-5 | J23: =SUMIF(REFUELLERS[2º ETAPA],Tabla1869[[#This Row],[2º ETAPA]],REFUELLERS[[CANT ]]) -> 1 | K23: =SUMIF(REFUELLERS[2º ETAPA],Tabla1869[[#This Row],[2º ETAPA]],REFUELLERS[V 2°]) -> 0 | L23: =IF(K23=0,"0",(IFERROR(LOOKUP(I23,Costos!$B$5:$B$100,Costos!$C$5:$C$100),0)))*Tabla1869[[#This Row],[PARA CAMB]] -> 0 | M23: =Tabla1869[[#This Row],[DÓLAR]]*$F$5 -> 0
A24: =A23+1 -> 11 | B24: FG-O-609-2 | C24: =SUMIF(REFUELLERS[1º ETAPA],Tabla186[[#This Row],[1º ETAPA]],REFUELLERS[CANT]) -> 1 | D24: =SUMIF(REFUELLERS[1º ETAPA],Tabla186[[#This Row],[1º ETAPA]],REFUELLERS[V 1°]) -> 0 | E24: =IF(D24=0,"0",(IFERROR(LOOKUP(B24,Costos!$B$5:$B$100,Costos!$C$5:$C$100),0)))*Tabla186[[#This Row],[PARA CAMB]] -> 0 | F24: =Tabla186[[#This Row],[DÓLAR]]*$F$5 -> 0 | H24: =H23+1 -> 11 | I24: SS630FE-5 | J24: =SUMIF(REFUELLERS[2º ETAPA],Tabla1869[[#This Row],[2º ETAPA]],REFUELLERS[[CANT ]]) -> 1 | K24: =SUMIF(REFUELLERS[2º ETAPA],Tabla1869[[#This Row],[2º ETAPA]],REFUELLERS[V 2°]) -> 1 | L24: =IF(K24=0,"0",(IFERROR(LOOKUP(I24,Costos!$B$5:$B$100,Costos!$C$5:$C$100),0)))*Tabla1869[[#This Row],[PARA CAMB]] -> 256.1 | M24: =Tabla1869[[#This Row],[DÓLAR]]*$F$5 -> 945841.33
A25: =A24+1 -> 12 | B25: I-622C5TB | C25: =SUMIF(REFUELLERS[1º ETAPA],Tabla186[[#This Row],[1º ETAPA]],REFUELLERS[CANT]) -> 4 | D25: =SUMIF(REFUELLERS[1º ETAPA],Tabla186[[#This Row],[1º ETAPA]],REFUELLERS[V 1°]) -> 0 | E25: =IF(D25=0,"0",(IFERROR(LOOKUP(B25,Costos!$B$5:$B$100,Costos!$C$5:$C$100),0)))*Tabla186[[#This Row],[PARA CAMB]] -> 0 | F25: =Tabla186[[#This Row],[DÓLAR]]*$F$5 -> 0
A26: =A25+1 -> 13 | B26: I-628C5TB | C26: =SUMIF(REFUELLERS[1º ETAPA],Tabla186[[#This Row],[1º ETAPA]],REFUELLERS[CANT]) -> 3 | D26: =SUMIF(REFUELLERS[1º ETAPA],Tabla186[[#This Row],[1º ETAPA]],REFUELLERS[V 1°]) -> 0 | E26: =IF(D26=0,"0",(IFERROR(LOOKUP(B26,Costos!$B$5:$B$100,Costos!$C$5:$C$100),0)))*Tabla186[[#This Row],[PARA CAMB]] -> 0 | F26: =Tabla186[[#This Row],[DÓLAR]]*$F$5 -> 0
A27: =A26+1 -> 14 | B27: I-63383TB | C27: =SUMIF(REFUELLERS[1º ETAPA],Tabla186[[#This Row],[1º ETAPA]],REFUELLERS[CANT]) -> 3 | D27: =SUMIF(REFUELLERS[1º ETAPA],Tabla186[[#This Row],[1º ETAPA]],REFUELLERS[V 1°]) -> 0 | E27: =IF(D27=0,"0",(IFERROR(LOOKUP(B27,Costos!$B$5:$B$100,Costos!$C$5:$C$100),0)))*Tabla186[[#This Row],[PARA CAMB]] -> 0 | F27: =Tabla186[[#This Row],[DÓLAR]]*$F$5 -> 0
A28: =A27+1 -> 15 | B28: I-633C5TB | C28: =SUMIF(REFUELLERS[1º ETAPA],Tabla186[[#This Row],[1º ETAPA]],REFUELLERS[CANT]) -> 8 | D28: =SUMIF(REFUELLERS[1º ETAPA],Tabla186[[#This Row],[1º ETAPA]],REFUELLERS[V 1°]) -> 3 | E28: =IF(D28=0,"0",(IFERROR(LOOKUP(B28,Costos!$B$5:$B$100,Costos!$C$5:$C$100),0)))*Tabla186[[#This Row],[PARA CAMB]] -> 768.3 | F28: =Tabla186[[#This Row],[DÓLAR]]*$F$5 -> 2837524
H30: =H7 -> REMPLAZO ELEMENTOS | K30: =D35+K35 -> 48 | L30: =E35+L35 -> 10225.91 | M30: =F35+M35 -> 37766842
H31: =H8 -> IMPOR Y NACIONALIZA | K31: =K8 -> 0.25 | L31: =L30*K31 -> 2556.4775 | M31: =L31*F5 -> 9441710.5
H32: TOTAL REFUELLERS | L32: =SUM(L30:L31) -> 12782.388 | M32: =SUM(M30:M31) -> 47208553
A34: PLANTAS | H34: PLANTAS
A35: TOTALES | C35: =SUBTOTAL(109,Tabla18610[CANT ISTA]) -> 78 | D35: =SUBTOTAL(109,Tabla18610[PARA CAMB]) -> 32 | E35: =SUBTOTAL(109,E37:E49) -> 6128.31 | F35: =SUBTOTAL(109,F37:F49) -> 22633381 | H35: TOTALES | J35: =SUM(Tabla186913[CANT ISTA]) -> 36 | K35: =SUM(Tabla186913[PARA CAMB]) -> 16 | L35: =SUBTOTAL(109,L37:L51) -> 4097.6 | M35: =SUBTOTAL(109,M37:M51) -> 15133461
A36: # | B36: 1º ETAPA | C36: CANT ISTA | D36: PARA CAMB | E36: DÓLAR | F36: PESOS | H36: # | I36: 2º ETAPA | J36: CANT ISTA | K36: PARA CAMB | L36: DÓLAR | M36: PESOS
A37: 1 | B37: ACO 51201L | C37: =SUMIF(PLANTAS[1º ETAPA],Tabla18610[[#This Row],[1º ETAPA]],PLANTAS[CANT]) -> 8 | D37: =SUMIF(PLANTAS[1º ETAPA],Tabla18610[[#This Row],[1º ETAPA]],PLANTAS[V 1°]) -> 4 | E37: =IF(D37=0,"0",(IFERROR(LOOKUP(B37,Costos!$B$5:$B$100,Costos!$C$5:$C$100),0)))*Tabla18610[[#This Row],[PARA CAMB]] -> 788 | F37: =Tabla18610[[#This Row],[DÓLAR]]*$F$5 -> 2910281 | H37: 1 | I37: SO-609C | J37: =SUMIF(PLANTAS[2º ETAPA],Tabla186913[[#This Row],[2º ETAPA]],PLANTAS[[CANT ]]) -> 1 | K37: =SUMIF(PLANTAS[2º ETAPA],Tabla186913[[#This Row],[2º ETAPA]],PLANTAS[V 2°]) -> 1 | L37: =IF(K37=0,"0",(IFERROR(LOOKUP(I37,Costos!$B$5:$B$100,Costos!$C$5:$C$100),0)))*Tabla186913[[#This Row],[PARA CAMB]] -> 256.1 | M37: =Tabla186913[[#This Row],[DÓLAR]]*$F$5 -> 945841.33
A38: =A37+1 -> 2 | B38: ACO 52401R | C38: =SUMIF(PLANTAS[1º ETAPA],Tabla18610[[#This Row],[1º ETAPA]],PLANTAS[CANT]) -> 1 | D38: =SUMIF(PLANTAS[1º ETAPA],Tabla18610[[#This Row],[1º ETAPA]],PLANTAS[V 1°]) -> 1 | E38: =IF(D38=0,"0",(IFERROR(LOOKUP(B38,Costos!$B$5:$B$100,Costos!$C$5:$C$100),0)))*Tabla18610[[#This Row],[PARA CAMB]] -> 256.55 | F38: =Tabla18610[[#This Row],[DÓLAR]]*$F$5 -> 947503.29 | H38: =H37+1 -> 2 | I38: SO-609V5 | J38: =SUMIF(PLANTAS[2º ETAPA],Tabla186913[[#This Row],[2º ETAPA]],PLANTAS[[CANT ]]) -> 2 | K38: =SUMIF(PLANTAS[2º ETAPA],Tabla186913[[#This Row],[2º ETAPA]],PLANTAS[V 2°]) -> 2 | L38: =IF(K38=0,"0",(IFERROR(LOOKUP(I38,Costos!$B$5:$B$100,Costos!$C$5:$C$100),0)))*Tabla186913[[#This Row],[PARA CAMB]] -> 512.2 | M38: =Tabla186913[[#This Row],[DÓLAR]]*$F$5 -> 1891682.7
A39: =A38+1 -> 3 | B39: CAA14-5SB | C39: =SUMIF(PLANTAS[1º ETAPA],Tabla18610[[#This Row],[1º ETAPA]],PLANTAS[CANT]) -> 6 | D39: =SUMIF(PLANTAS[1º ETAPA],Tabla18610[[#This Row],[1º ETAPA]],PLANTAS[V 1°]) -> 0 | E39: =IF(D39=0,"0",(IFERROR(LOOKUP(B39,Costos!$B$5:$B$100,Costos!$C$5:$C$100),0)))*Tabla18610[[#This Row],[PARA CAMB]] -> 0 | F39: =Tabla18610[[#This Row],[DÓLAR]]*$F$5 -> 0 | H39: =H38+1 -> 3 | I39: SO-614FB5 | J39: =SUMIF(PLANTAS[2º ETAPA],Tabla186913[[#This Row],[2º ETAPA]],PLANTAS[[CANT ]]) -> 1 | K39: =SUMIF(PLANTAS[2º ETAPA],Tabla186913[[#This Row],[2º ETAPA]],PLANTAS[V 2°]) -> 0 | L39: =IF(K39=0,"0",(IFERROR(LOOKUP(I39,Costos!$B$5:$B$100,Costos!$C$5:$C$100),0)))*Tabla186913[[#This Row],[PARA CAMB]] -> 0 | M39: =Tabla186913[[#This Row],[DÓLAR]]*$F$5 -> 0
A40: =A39+1 -> 4 | B40: CAA22-5SB | C40: =SUMIF(PLANTAS[1º ETAPA],Tabla18610[[#This Row],[1º ETAPA]],PLANTAS[CANT]) -> 1 | D40: =SUMIF(PLANTAS[1º ETAPA],Tabla18610[[#This Row],[1º ETAPA]],PLANTAS[V 1°]) -> 1 | E40: =IF(D40=0,"0",(IFERROR(LOOKUP(B40,Costos!$B$5:$B$100,Costos!$C$5:$C$100),0)))*Tabla18610[[#This Row],[PARA CAMB]] -> 100.92 | F40: =Tabla18610[[#This Row],[DÓLAR]]*$F$5 -> 372722.79 | H40: =H39+1 -> 4 | I40: SO-623VA5 | J40: =SUMIF(PLANTAS[2º ETAPA],Tabla186913[[#This Row],[2º ETAPA]],PLANTAS[[CANT ]]) -> 1 | K40: =SUMIF(PLANTAS[2º ETAPA],Tabla186913[[#This Row],[2º ETAPA]],PLANTAS[V 2°]) -> 0 | L40: =IF(K40=0,"0",(IFERROR(LOOKUP(I40,Costos!$B$5:$B$100,Costos!$C$5:$C$100),0)))*Tabla186913[[#This Row],[PARA CAMB]] -> 0 | M40: =Tabla186913[[#This Row],[DÓLAR]]*$F$5 -> 0
A41: =A40+1 -> 5 | B41: CAA28-5SB | C41: =SUMIF(PLANTAS[1º ETAPA],Tabla18610[[#This Row],[1º ETAPA]],PLANTAS[CANT]) -> 37 | D41: =SUMIF(PLANTAS[1º ETAPA],Tabla18610[[#This Row],[1º ETAPA]],PLANTAS[V 1°]) -> 14 | E41: =IF(D41=0,"0",(IFERROR(LOOKUP(B41,Costos!$B$5:$B$100,Costos!$C$5:$C$100),0)))*Tabla18610[[#This Row],[PARA CAMB]] -> 2836.26 | F41: =Tabla18610[[#This Row],[DÓLAR]]*$F$5 -> 10475017 | H41: =H40+1 -> 5 | I41: SO-629C | J41: =SUMIF(PLANTAS[2º ETAPA],Tabla186913[[#This Row],[2º ETAPA]],PLANTAS[[CANT ]]) -> 3 | K41: =SUMIF(PLANTAS[2º ETAPA],Tabla186913[[#This Row],[2º ETAPA]],PLANTAS[V 2°]) -> 2 | L41: =IF(K41=0,"0",(IFERROR(LOOKUP(I41,Costos!$B$5:$B$100,Costos!$C$5:$C$100),0)))*Tabla186913[[#This Row],[PARA CAMB]] -> 512.2 | M41: =Tabla186913[[#This Row],[DÓLAR]]*$F$5 -> 1891682.7
A42: =A41+1 -> 6 | B42: FG-O-512-2 | C42: =SUMIF(PLANTAS[1º ETAPA],Tabla18610[[#This Row],[1º ETAPA]],PLANTAS[CANT]) -> 1 | D42: =SUMIF(PLANTAS[1º ETAPA],Tabla18610[[#This Row],[1º ETAPA]],PLANTAS[V 1°]) -> 0 | E42: =IF(D42=0,"0",(IFERROR(LOOKUP(B42,Costos!$B$5:$B$100,Costos!$C$5:$C$100),0)))*Tabla18610[[#This Row],[PARA CAMB]] -> 0 | F42: =Tabla18610[[#This Row],[DÓLAR]]*$F$5 -> 0 | H42: =H41+1 -> 6 | I42: SO-630PV5 | J42: =SUMIF(PLANTAS[2º ETAPA],Tabla186913[[#This Row],[2º ETAPA]],PLANTAS[[CANT ]]) -> 1 | K42: =SUMIF(PLANTAS[2º ETAPA],Tabla186913[[#This Row],[2º ETAPA]],PLANTAS[V 2°]) -> 1 | L42: =IF(K42=0,"0",(IFERROR(LOOKUP(I42,Costos!$B$5:$B$100,Costos!$C$5:$C$100),0)))*Tabla186913[[#This Row],[PARA CAMB]] -> 256.1 | M42: =Tabla186913[[#This Row],[DÓLAR]]*$F$5 -> 945841.33
A43: =A42+1 -> 7 | B43: FG-O-609-2 | C43: =SUMIF(PLANTAS[1º ETAPA],Tabla18610[[#This Row],[1º ETAPA]],PLANTAS[CANT]) -> 2 | D43: =SUMIF(PLANTAS[1º ETAPA],Tabla18610[[#This Row],[1º ETAPA]],PLANTAS[V 1°]) -> 0 | E43: =IF(D43=0,"0",(IFERROR(LOOKUP(B43,Costos!$B$5:$B$100,Costos!$C$5:$C$100),0)))*Tabla18610[[#This Row],[PARA CAMB]] -> 0 | F43: =Tabla18610[[#This Row],[DÓLAR]]*$F$5 -> 0 | H43: =H42+1 -> 7 | I43: SS609F-5 | J43: =SUMIF(PLANTAS[2º ETAPA],Tabla186913[[#This Row],[2º ETAPA]],PLANTAS[[CANT ]]) -> 3 | K43: =SUMIF(PLANTAS[2º ETAPA],Tabla186913[[#This Row],[2º ETAPA]],PLANTAS[V 2°]) -> 0 | L43: =IF(K43=0,"0",(IFERROR(LOOKUP(I43,Costos!$B$5:$B$100,Costos!$C$5:$C$100),0)))*Tabla186913[[#This Row],[PARA CAMB]] -> 0 | M43: =Tabla186913[[#This Row],[DÓLAR]]*$F$5 -> 0
A44: =A43+1 -> 8 | B44: FO614-PL5 | C44: =SUMIF(PLANTAS[1º ETAPA],Tabla18610[[#This Row],[1º ETAPA]],PLANTAS[CANT]) -> 6 | D44: =SUMIF(PLANTAS[1º ETAPA],Tabla18610[[#This Row],[1º ETAPA]],PLANTAS[V 1°]) -> 0 | E44: =IF(D44=0,"0",(IFERROR(LOOKUP(B44,Costos!$B$5:$B$100,Costos!$C$5:$C$100),0)))*Tabla18610[[#This Row],[PARA CAMB]] -> 0 | F44: =Tabla18610[[#This Row],[DÓLAR]]*$F$5 -> 0 | H44: =H43+1 -> 8 | I44: SS609FB-5 | J44: =SUMIF(PLANTAS[2º ETAPA],Tabla186913[[#This Row],[2º ETAPA]],PLANTAS[[CANT ]]) -> 3 | K44: =SUMIF(PLANTAS[2º ETAPA],Tabla186913[[#This Row],[2º ETAPA]],PLANTAS[V 2°]) -> 0 | L44: =IF(K44=0,"0",(IFERROR(LOOKUP(I44,Costos!$B$5:$B$100,Costos!$C$5:$C$100),0)))*Tabla186913[[#This Row],[PARA CAMB]] -> 0 | M44: =Tabla186913[[#This Row],[DÓLAR]]*$F$5 -> 0
A45: =A44+1 -> 9 | B45: I-61487TB | C45: =SUMIF(PLANTAS[1º ETAPA],Tabla18610[[#This Row],[1º ETAPA]],PLANTAS[CANT]) -> 2 | D45: =SUMIF(PLANTAS[1º ETAPA],Tabla18610[[#This Row],[1º ETAPA]],PLANTAS[V 1°]) -> 2 | E45: =IF(D45=0,"0",(IFERROR(LOOKUP(B45,Costos!$B$5:$B$100,Costos!$C$5:$C$100),0)))*Tabla18610[[#This Row],[PARA CAMB]] -> 300.46 | F45: =Tabla18610[[#This Row],[DÓLAR]]*$F$5 -> 1109673.9 | H45: =H44+1 -> 9 | I45: SS609FE-5 | J45: =SUMIF(PLANTAS[2º ETAPA],Tabla186913[[#This Row],[2º ETAPA]],PLANTAS[[CANT ]]) -> 10 | K45: =SUMIF(PLANTAS[2º ETAPA],Tabla186913[[#This Row],[2º ETAPA]],PLANTAS[V 2°]) -> 3 | L45: =IF(K45=0,"0",(IFERROR(LOOKUP(I45,Costos!$B$5:$B$100,Costos!$C$5:$C$100),0)))*Tabla186913[[#This Row],[PARA CAMB]] -> 768.3 | M45: =Tabla186913[[#This Row],[DÓLAR]]*$F$5 -> 2837524
A46: =A45+1 -> 10 | B46: I-62287TB | C46: =SUMIF(PLANTAS[1º ETAPA],Tabla18610[[#This Row],[1º ETAPA]],PLANTAS[CANT]) -> 4 | D46: =SUMIF(PLANTAS[1º ETAPA],Tabla18610[[#This Row],[1º ETAPA]],PLANTAS[V 1°]) -> 4 | E46: =IF(D46=0,"0",(IFERROR(LOOKUP(B46,Costos!$B$5:$B$100,Costos!$C$5:$C$100),0)))*Tabla18610[[#This Row],[PARA CAMB]] -> 722.6 | F46: =Tabla18610[[#This Row],[DÓLAR]]*$F$5 -> 2668742.5 | H46: =H45+1 -> 10 | I46: SS609FF-5 | J46: =SUMIF(PLANTAS[2º ETAPA],Tabla186913[[#This Row],[2º ETAPA]],PLANTAS[[CANT ]]) -> 2 | K46: =SUMIF(PLANTAS[2º ETAPA],Tabla186913[[#This Row],[2º ETAPA]],PLANTAS[V 2°]) -> 2 | L46: =IF(K46=0,"0",(IFERROR(LOOKUP(I46,Costos!$B$5:$B$100,Costos!$C$5:$C$100),0)))*Tabla186913[[#This Row],[PARA CAMB]] -> 512.2 | M46: =Tabla186913[[#This Row],[DÓLAR]]*$F$5 -> 1891682.7
...

Sheet Costos
B1: #VALUE! | C1: {=_FV(B1,"Precio")} -> 3693.25
A3: ELEMENTOS FILTRANTES ETAPA 1 | I3: ELEMENTOS FILTRANTES ETAPA 2
A4: ITEM | B4: REFERENCIA | C4: VALOR US$ | D4: VALOR COL$ | E4: CANTIDAD | F4: TOTAL US$ | G4: TOTAL COL$ | I4: ITEM | J4: REFERENCIA | K4: VALOR US$ | L4: VALOR COL$ | M4: CANTIDAD | N4: TOTAL US$ | O4: TOTAL COL$
A5: 1 | B5: ACO 51201L | C5: 197 | D5: =C5*$C$1 -> 727570.25 | E5: 10 | F5: =Tabla33[[#This Row],[VALOR US$]]*Tabla33[[#This Row],[CANTIDAD]] -> 1970 | G5: =Tabla33[[#This Row],[TOTAL US$]]*$C$1 -> 7275702.5 | I5: 1 | J5: SM-436FB-5 | K5: 277.58 | L5: =K5*$C$1 -> 1025172.3 | M5: 1 | N5: =Tabla333[[#This Row],[VALOR US$]]*Tabla333[[#This Row],[CANTIDAD]] -> 277.58 | O5: =Tabla333[[#This Row],[TOTAL US$]]*$C$1 -> 1025172.3
